<?xml version="1.0" encoding="utf-8"?>
<!-- =================================================================================== -->
<!-- |    This document was autogenerated by xacro from gogoro_and_thormang3.xacro     | -->
<!-- |    EDITING THIS FILE BY HAND IS NOT RECOMMENDED                                 | -->
<!-- =================================================================================== -->
<robot name="gogoro_and_thormang3">
  <!-- ros_control plugin -->
  <gazebo>
    <plugin filename="libgazebo_ros_control.so" name="gazebo_ros_control">
      <robotNamespace>/thormang3</robotNamespace>
      <robotSimType>gazebo_ros_control/DefaultRobotHWSim</robotSimType>
      <legacyModeNS>true</legacyModeNS>
    </plugin>
  </gazebo>
  <gazebo>
    <plugin filename="libgazebo_ros_p3d.so" name="ground_truth">
      <frameName>map</frameName>
      <bodyName>pelvis_link</bodyName>
      <topicName>odom</topicName>
      <updateRate>100.0</updateRate>
    </plugin>
  </gazebo>
  <gazebo reference="cam_link">
    <sensor name="center_camera_gz" type="camera">
      <update_rate>30.0</update_rate>
      <camera name="web_cam">
        <!--<horizontal_fov>1.3962634</horizontal_fov> -->
        <horizontal_fov>1.7</horizontal_fov>
        <image>
          <width>640</width>
          <height>480</height>
          <format>R8G8B8</format>
        </image>
        <clip>
          <near>0.02</near>
          <far>300</far>
        </clip>
      </camera>
      <plugin filename="libgazebo_ros_camera.so" name="camera_controller">
        <alwaysOn>true</alwaysOn>
        <updateRate>0.0</updateRate>
        <cameraName>/robotis/sensor/camera</cameraName>
        <imageTopicName>/robotis/sensor/image_raw</imageTopicName>
        <cameraInfoTopicName>/robotis/sensor/camera_info</cameraInfoTopicName>
        <frameName>cam_link</frameName>
        <hackBaseline>0.07</hackBaseline>
        <distortionK1>0.0</distortionK1>
        <distortionK2>0.0</distortionK2>
        <distortionK3>0.0</distortionK3>
        <distortionT1>0.0</distortionT1>
        <distortionT2>0.0</distortionT2>
      </plugin>
    </sensor>
  </gazebo>
  <gazebo reference="lidar_link">
    <sensor name="head_hokuyo_sensor" type="gpu_ray">
      <pose>0 0 0 0 0 0</pose>
      <visualize>false</visualize>
      <update_rate>40</update_rate>
      <ray>
        <scan>
          <horizontal>
            <samples>720</samples>
            <resolution>1</resolution>
            <min_angle>-1.3</min_angle>
            <max_angle>1.0</max_angle>
          </horizontal>
        </scan>
        <range>
          <min>0.10</min>
          <max>6.0</max>
          <resolution>0.01</resolution>
        </range>
        <noise>
          <type>gaussian</type>
          <mean>0.0</mean>
          <stddev>0.01</stddev>
        </noise>
      </ray>
      <plugin filename="libgazebo_ros_gpu_laser.so" name="gazebo_ros_head_hokuyo_controller">
        <topicName>/robotis/sensor/scan</topicName>
        <frameName>lidar_link</frameName>
      </plugin>
    </sensor>
  </gazebo>
  <gazebo>
    <plugin filename="libgazebo_ros_imu.so" name="imu_plugin">
      <alwaysOn>true</alwaysOn>
      <bodyName>imu_link</bodyName>
      <topicName>/robotis/sensor/imu</topicName>
      <serviceName>imu_service</serviceName>
      <gaussianNoise>0.0</gaussianNoise>
      <updateRate>10.0</updateRate>
      <imu>
        <noise>
          <type>gaussian</type>
          <rate>
            <mean>0.0</mean>
            <stddev>2e-4</stddev>
            <bias_mean>0.0000075</bias_mean>
            <bias_stddev>0.0000008</bias_stddev>
          </rate>
          <accel>
            <mean>0.0</mean>
            <stddev>1.7e-2</stddev>
            <bias_mean>0.1</bias_mean>
            <bias_stddev>0.001</bias_stddev>
          </accel>
        </noise>
      </imu>
    </plugin>
  </gazebo>
  <!-- World -->
  <gazebo reference="world">
  </gazebo>
  <!-- Base -->
  <gazebo reference="base">
  </gazebo>
  <!-- Body-->
  <gazebo reference="pelvis_link">
    <mu1>0.2</mu1>
    <mu2>0.2</mu2>
    <material>Gazebo/Grey</material>
  </gazebo>
  <gazebo reference="chest_link">
    <mu1>0.2</mu1>
    <mu2>0.2</mu2>
    <material>Gazebo/Grey</material>
  </gazebo>
  <!-- Head -->
  <gazebo reference="head_y_link">
    <mu1>0.2</mu1>
    <mu2>0.2</mu2>
    <material>Gazebo/Grey</material>
  </gazebo>
  <gazebo reference="head_p_link">
    <mu1>0.2</mu1>
    <mu2>0.2</mu2>
    <material>Gazebo/Grey</material>
  </gazebo>
  <gazebo reference="lidar_link">
  </gazebo>
  <!-- Left Arm -->
  <gazebo reference="l_arm_sh_p1_link">
    <mu1>0.2</mu1>
    <mu2>0.2</mu2>
    <material>Gazebo/Grey</material>
  </gazebo>
  <gazebo reference="l_arm_sh_r_link">
    <mu1>0.2</mu1>
    <mu2>0.2</mu2>
    <material>Gazebo/Grey</material>
  </gazebo>
  <gazebo reference="l_arm_sh_p2_link">
    <mu1>0.2</mu1>
    <mu2>0.2</mu2>
    <material>Gazebo/Grey</material>
  </gazebo>
  <gazebo reference="l_arm_el_y_link">
    <mu1>0.2</mu1>
    <mu2>0.2</mu2>
    <material>Gazebo/Grey</material>
  </gazebo>
  <gazebo reference="l_arm_wr_r_link">
    <mu1>0.2</mu1>
    <mu2>0.2</mu2>
    <material>Gazebo/Grey</material>
  </gazebo>
  <gazebo reference="l_arm_wr_y_link">
    <mu1>0.2</mu1>
    <mu2>0.2</mu2>
    <material>Gazebo/Grey</material>
  </gazebo>
  <gazebo reference="l_arm_wr_p_link">
    <mu1>0.2</mu1>
    <mu2>0.2</mu2>
    <material>Gazebo/Grey</material>
  </gazebo>
  <gazebo reference="l_arm_grip_link">
    <mu1>0.2</mu1>
    <mu2>0.2</mu2>
    <material>Gazebo/Grey</material>
  </gazebo>
  <gazebo reference="l_arm_grip_1_link">
    <mu1>0.2</mu1>
    <mu2>0.2</mu2>
    <material>Gazebo/Grey</material>
  </gazebo>
  <gazebo reference="l_arm_end_link">
    <mu1>0.2</mu1>
    <mu2>0.2</mu2>
    <material>Gazebo/Red</material>
  </gazebo>
  <!-- Right Arm -->
  <gazebo reference="r_arm_sh_p1_link">
    <mu1>0.2</mu1>
    <mu2>0.2</mu2>
    <material>Gazebo/Grey</material>
  </gazebo>
  <gazebo reference="r_arm_sh_r_link">
    <mu1>0.2</mu1>
    <mu2>0.2</mu2>
    <material>Gazebo/Grey</material>
  </gazebo>
  <gazebo reference="r_arm_sh_p2_link">
    <mu1>0.2</mu1>
    <mu2>0.2</mu2>
    <material>Gazebo/Grey</material>
  </gazebo>
  <gazebo reference="r_arm_el_y_link">
    <mu1>0.2</mu1>
    <mu2>0.2</mu2>
    <material>Gazebo/Grey</material>
  </gazebo>
  <gazebo reference="r_arm_wr_r_link">
    <mu1>0.2</mu1>
    <mu2>0.2</mu2>
    <material>Gazebo/Grey</material>
  </gazebo>
  <gazebo reference="r_arm_wr_y_link">
    <mu1>0.2</mu1>
    <mu2>0.2</mu2>
    <material>Gazebo/Grey</material>
  </gazebo>
  <gazebo reference="r_arm_wr_p_link">
    <mu1>0.2</mu1>
    <mu2>0.2</mu2>
    <material>Gazebo/Grey</material>
  </gazebo>
  <gazebo reference="r_arm_grip_link">
    <mu1>0.2</mu1>
    <mu2>0.2</mu2>
    <material>Gazebo/Grey</material>
  </gazebo>
  <gazebo reference="r_arm_grip_1_link">
    <mu1>0.2</mu1>
    <mu2>0.2</mu2>
    <material>Gazebo/Grey</material>
  </gazebo>
  <gazebo reference="r_arm_end_link">
    <mu1>0.2</mu1>
    <mu2>0.2</mu2>
    <material>Gazebo/Red</material>
  </gazebo>
  <!-- Left Leg -->
  <gazebo reference="l_leg_hip_y_link">
    <mu1>0.2</mu1>
    <mu2>0.2</mu2>
    <material>Gazebo/Grey</material>
  </gazebo>
  <gazebo reference="l_leg_hip_r_link">
    <mu1>0.2</mu1>
    <mu2>0.2</mu2>
    <material>Gazebo/Grey</material>
  </gazebo>
  <gazebo reference="l_leg_hip_p_link">
    <mu1>0.2</mu1>
    <mu2>0.2</mu2>
    <material>Gazebo/Grey</material>
  </gazebo>
  <gazebo reference="l_leg_kn_p_link">
    <mu1>0.2</mu1>
    <mu2>0.2</mu2>
    <material>Gazebo/Grey</material>
  </gazebo>
  <gazebo reference="l_leg_an_p_link">
    <mu1>0.2</mu1>
    <mu2>0.2</mu2>
    <material>Gazebo/Grey</material>
  </gazebo>
  <gazebo reference="l_leg_an_r_link">
    <mu1>0.2</mu1>
    <mu2>0.2</mu2>
    <material>Gazebo/Grey</material>
  </gazebo>
  <gazebo reference="l_leg_foot_link">
    <kp>100000.0</kp>
    <kd>100.0</kd>
    <mu1>1.5</mu1>
    <mu2>1.5</mu2>
    <fdir1>1 0 0</fdir1>
    <maxVel>1.0</maxVel>
    <minDepth>0.0</minDepth>
    <material>Gazebo/Grey</material>
  </gazebo>
  <!-- Right Leg -->
  <gazebo reference="r_leg_hip_y_link">
    <mu1>0.2</mu1>
    <mu2>0.2</mu2>
    <material>Gazebo/Grey</material>
  </gazebo>
  <gazebo reference="r_leg_hip_r_link">
    <mu1>0.2</mu1>
    <mu2>0.2</mu2>
    <material>Gazebo/Grey</material>
  </gazebo>
  <gazebo reference="r_leg_hip_p_link">
    <mu1>0.2</mu1>
    <mu2>0.2</mu2>
    <material>Gazebo/Grey</material>
  </gazebo>
  <gazebo reference="r_leg_kn_p_link">
    <mu1>0.2</mu1>
    <mu2>0.2</mu2>
    <material>Gazebo/Grey</material>
  </gazebo>
  <gazebo reference="r_leg_an_p_link">
    <mu1>0.2</mu1>
    <mu2>0.2</mu2>
    <material>Gazebo/Grey</material>
  </gazebo>
  <gazebo reference="r_leg_an_r_link">
    <mu1>0.2</mu1>
    <mu2>0.2</mu2>
    <material>Gazebo/Grey</material>
  </gazebo>
  <gazebo reference="r_leg_foot_link">
    <kp>100000.0</kp>
    <kd>100.0</kd>
    <mu1>1.5</mu1>
    <mu2>1.5</mu2>
    <fdir1>1 0 0</fdir1>
    <maxVel>1.0</maxVel>
    <minDepth>0.0</minDepth>
    <material>Gazebo/Grey</material>
  </gazebo>
  <material name="black">
    <color rgba="0.0 0.0 0.0 1.0"/>
  </material>
  <material name="blue">
    <color rgba="0.0 0.0 0.8 1.0"/>
  </material>
  <material name="green">
    <color rgba="0.0 0.8 0.0 1.0"/>
  </material>
  <material name="grey">
    <color rgba="0.2 0.2 0.2 1.0"/>
  </material>
  <material name="orange">
    <color rgba="1.0 0.423529411765 0.0392156862745 1.0"/>
  </material>
  <material name="brown">
    <color rgba="0.870588235294 0.811764705882 0.764705882353 1.0"/>
  </material>
  <material name="red">
    <color rgba="0.8 0.0 0.0 1.0"/>
  </material>
  <material name="white">
    <color rgba="1.0 1.0 1.0 1.0"/>
  </material>
  <!-- Used for fixing robot -->
  <!--
  <link name="world">
  </link>

  <joint name="world_fixed" type="fixed">
    <origin xyz="0 0 0" rpy="0 0 0"/>
    <parent link="world"/>
    <child link="base"/>
  </joint>

  <link name="base">
  </link>

  <joint name="base_fixed" type="fixed">
    <origin xyz="0 0 0.723" rpy="0 0 0"/>
    <parent link="base"/>
    <child link="pelvis_link"/>
  </joint>
-->
  <!-- pelvis_link -->
  <link name="pelvis_link">
    <collision>
      <origin xyz="-0.01 0 0.07" rpy="0 0 0"/>
      <geometry>
        <box size="0.2 0.25 0.17" />
      </geometry>
    </collision>
    <visual>
      <origin rpy="0 0 0" xyz="0 0 0"/>
      <geometry>
        <mesh filename="package://gogoro_description/meshes/thormang3/robotis_pelvis_link.obj" scale="0.001 0.001 0.001"/>
      </geometry>
      <material name="grey"/>
    </visual>
    <inertial>
      <origin rpy="0 0 0" xyz="-0.011 0.000 0.058"/>
      <mass value="6.869"/>
      <inertia ixx="1.0" ixy="0.0" ixz="0.0" iyy="1.0" iyz="0.0" izz="1.0"/>
      <!--<inertia ixx="0.03603" ixy="0.0" ixz="0.00016" iyy="0.02210" iyz="0.0" izz="0.03830" />-->
    </inertial>
  </link>
  <!-- torso yaw joint -->
  <joint name="torso_y" type="revolute">
    <parent link="pelvis_link"/>
    <child link="chest_link"/>
    <origin rpy="0 0 0" xyz="0 0 0.1705"/>
    <axis xyz="0 0 1"/>
    <limit effort="1000" lower="-1.8849555924" upper="1.8849555924" velocity="6.5"/>
    <dynamics damping="0.1" friction="0.0"/>
  </joint>
  <transmission name="torso_y_tran">
    <type>transmission_interface/SimpleTransmission</type>
    <joint name="torso_y">
      <hardwareInterface>EffortJointInterface</hardwareInterface>
    </joint>
    <actuator name="torso_y_motor">
      <hardwareInterface>EffortJointInterface</hardwareInterface>
      <mechanicalReduction>1</mechanicalReduction>
    </actuator>
  </transmission>
  <!-- chest_link -->
  <link name="chest_link">
    <collision>
      <origin xyz="-0.01 0 0.11" rpy="0 0 0"/>
      <geometry>
        <box size="0.2 0.25 0.23" />
      </geometry>
    </collision>
    <visual>
      <origin rpy="0 0 0" xyz="0 0 0"/>
      <geometry>
        <mesh filename="package://gogoro_description/meshes/thormang3/robotis_chest_link.obj" scale="0.001 0.001 0.001"/>
      </geometry>
      <material name="grey"/>
    </visual>
    <inertial>
      <origin rpy="0 0 0" xyz="-0.007 0.000 0.109"/>
      <mass value="5.383"/>
      <inertia ixx="1.0" ixy="0.0" ixz="0.0" iyy="1.0" iyz="0.0" izz="1.0"/>
      <!--<inertia ixx="0.04710" ixy="0.0" ixz="0.04710" iyy="0.02554" iyz="0.0" izz="0.03094" />-->
    </inertial>
  </link>
  <!-- imu joint -->
  <joint name="imu_fixed" type="fixed">
    <parent link="pelvis_link"/>
    <child link="imu_link"/>
    <origin rpy="0 0 3.141592654" xyz="0.03 0 0.0"/>
  </joint>
  <link name="imu_link">
  </link>
  <!-- left shoulder pitch 1 joint -->
  <joint name="l_arm_sh_p1" type="revolute">
    <axis xyz="0 1 0"/>
    <origin rpy="0 0 0" xyz="0.0 0.152 0.16"/>
    <parent link="chest_link"/>
    <child link="l_arm_sh_p1_link"/>
    <limit effort="1000" lower="-1.570796327" upper="1.570796327" velocity="6.5"/>
    <dynamics damping="0.1" friction="0.0"/>
  </joint>
  <transmission name="l_arm_sh_p1_tran">
    <type>transmission_interface/SimpleTransmission</type>
    <joint name="l_arm_sh_p1">
      <hardwareInterface>EffortJointInterface</hardwareInterface>
    </joint>
    <actuator name="l_arm_sh_p1_motor">
      <hardwareInterface>EffortJointInterface</hardwareInterface>
      <mechanicalReduction>1</mechanicalReduction>
    </actuator>
  </transmission>
  <!-- left shoulder pitch 1 link -->
  <link name="l_arm_sh_p1_link">
    	  <collision>
      	    <origin xyz="0 0.03 -0.01" rpy="0 0 0"/>
      	    <geometry>
              <box size="0.15 0.1 0.09" />
      	    </geometry>
    	  </collision>
    <visual>
      <origin rpy="0 0 0" xyz="0 0 0"/>
      <geometry>
        <mesh filename="package://gogoro_description/meshes/thormang3/robotis_l_arm_sh_p1_link.obj" scale="0.001 0.001 0.001"/>
      </geometry>
      <material name="grey"/>
    </visual>
    <inertial>
      <origin rpy="0 0 0" xyz="-0.003 0.020 -0.005"/>
      <mass value="0.194"/>
      <inertia ixx="1.0" ixy="0.0" ixz="0.0" iyy="1.0" iyz="0.0" izz="1.0"/>
      <!--<inertia ixx="0.00018" ixy="0.0" ixz="0.0" iyy="0.00058" iyz="0.00004" izz="0.00057" />-->
    </inertial>
  </link>
  <!-- left shoulder roll joint -->
  <joint name="l_arm_sh_r" type="revolute">
    <axis xyz="-1 0 0"/>
    <origin rpy="0 0 0" xyz="0.057 0.060 -0.039"/>
    <parent link="l_arm_sh_p1_link"/>
    <child link="l_arm_sh_r_link"/>
    <limit effort="1000" lower="-1.570796327" upper="1.570796327" velocity="6.5"/>
    <dynamics damping="0.1" friction="0.0"/>
  </joint>
  <transmission name="l_arm_sh_r_tran">
    <type>transmission_interface/SimpleTransmission</type>
    <joint name="l_arm_sh_r">
      <hardwareInterface>EffortJointInterface</hardwareInterface>
    </joint>
    <actuator name="l_arm_sh_r_motor">
      <hardwareInterface>EffortJointInterface</hardwareInterface>
      <mechanicalReduction>1</mechanicalReduction>
    </actuator>
  </transmission>
  <!-- left shoulder roll link -->
  <link name="l_arm_sh_r_link">
    	  <collision>
      	    <origin xyz="-0.057 0 0" rpy="0 0 0"/>
      	    <geometry>
              <box size="0.14 0.09 0.09" />
      	    </geometry>
    	  </collision>
    <visual>
      <origin rpy="0 0 0" xyz="0 0 0"/>
      <geometry>
        <mesh filename="package://gogoro_description/meshes/thormang3/robotis_l_arm_sh_r_link.obj" scale="0.001 0.001 0.001"/>
      </geometry>
      <material name="grey"/>
    </visual>
    <inertial>
      <origin rpy="0 0 0" xyz="-0.060 0.002 0.000"/>
      <mass value="0.875"/>
      <inertia ixx="1.0" ixy="0.0" ixz="0.0" iyy="1.0" iyz="0.0" izz="1.0"/>
      <!--<inertia ixx="0.00043" ixy="0.0" ixz="0.0" iyy="0.00112" iyz="0.0" izz="0.00113" />-->
    </inertial>
  </link>
  <!-- left shoulder pitch 2 joint -->
  <joint name="l_arm_sh_p2" type="revolute">
    <axis xyz="0 1 0"/>
    <origin rpy="0 0 0" xyz="-0.057 0.033 0.0"/>
    <parent link="l_arm_sh_r_link"/>
    <child link="l_arm_sh_p2_link"/>
    <limit effort="1000" lower="-1.570796327" upper="1.570796327" velocity="6.5"/>
    <dynamics damping="0.1" friction="0.0"/>
  </joint>
  <transmission name="l_arm_sh_p2_tran">
    <type>transmission_interface/SimpleTransmission</type>
    <joint name="l_arm_sh_p2">
      <hardwareInterface>EffortJointInterface</hardwareInterface>
    </joint>
    <actuator name="l_arm_sh_p2_motor">
      <hardwareInterface>EffortJointInterface</hardwareInterface>
      <mechanicalReduction>1</mechanicalReduction>
    </actuator>
  </transmission>
  <!-- left shoulder pitch2 link -->
  <link name="l_arm_sh_p2_link">
    	  <collision>
      	    <origin xyz="0.01 0.11 0" rpy="0 0 0"/>
      	    <geometry>
              <box size="0.1 0.24 0.13" />
      	    </geometry>
    	  </collision>
    <visual>
      <origin rpy="0 0 0" xyz="0 0 0"/>
      <geometry>
        <mesh filename="package://gogoro_description/meshes/thormang3/robotis_l_arm_sh_p2_link.obj" scale="0.001 0.001 0.001"/>
      </geometry>
      <material name="grey"/>
    </visual>
    <inertial>
      <origin rpy="0 0 0" xyz="0.000 0.073 0.000"/>
      <mass value="1.122"/>
      <inertia ixx="1.0" ixy="0.0" ixz="0.0" iyy="1.0" iyz="0.0" izz="1.0"/>
      <!--<inertia ixx="0.00277" ixy="-0.00002" ixz="-0.00001" iyy="0.00090" iyz="-0.00004" izz="0.00255" />-->
    </inertial>
  </link>
  <!-- left elbow yaw joint -->
  <joint name="l_arm_el_y" type="revolute">
    <axis xyz="0 0 -1"/>
    <origin rpy="0 0 0" xyz="0.030 0.187 0.057"/>
    <parent link="l_arm_sh_p2_link"/>
    <child link="l_arm_el_y_link"/>
    <limit effort="1000" lower="-1.2566370616" upper="1.2566370616" velocity="6.5"/>
    <dynamics damping="0.1" friction="0.0"/>
  </joint>
  <transmission name="l_arm_el_y_tran">
    <type>transmission_interface/SimpleTransmission</type>
    <joint name="l_arm_el_y">
      <hardwareInterface>EffortJointInterface</hardwareInterface>
    </joint>
    <actuator name="l_arm_el_y_motor">
      <hardwareInterface>EffortJointInterface</hardwareInterface>
      <mechanicalReduction>1</mechanicalReduction>
    </actuator>
  </transmission>
  <!-- left elbow yaw link -->
  <link name="l_arm_el_y_link">
    	  <collision>
      	    <origin xyz="0.08 0.01 -0.057" rpy="0 0 0"/>
      	    <geometry>
              <box size="0.17 0.1 0.08" />
      	    </geometry>
    	  </collision>
    <visual>
      <origin rpy="0 0 0" xyz="0 0 0"/>
      <geometry>
        <mesh filename="package://gogoro_description/meshes/thormang3/robotis_l_arm_el_y_link.obj" scale="0.001 0.001 0.001"/>
      </geometry>
      <material name="grey"/>
    </visual>
    <inertial>
      <origin rpy="0 0 0" xyz="0.042 0.012 -0.058"/>
      <mass value="1.357"/>
      <inertia ixx="1.0" ixy="0.0" ixz="0.0" iyy="1.0" iyz="0.0" izz="1.0"/>
      <!--<inertia ixx="0.00152" ixy="-0.00100" ixz="-0.00006" iyy="0.00560" iyz="-0.00002" izz="0.00528" />-->
    </inertial>
  </link>
  <!-- left wrist roll joint -->
  <joint name="l_arm_wr_r" type="revolute">
    <axis xyz="1 0 0"/>
    <origin rpy="0 0 0" xyz="0.171 0.030 -0.057"/>
    <parent link="l_arm_el_y_link"/>
    <child link="l_arm_wr_r_link"/>
    <limit effort="1000" lower="-2.8274333886" upper="2.8274333886" velocity="6.5"/>
    <dynamics damping="0.1" friction="0.0"/>
  </joint>
  <transmission name="l_arm_wr_r_tran">
    <type>transmission_interface/SimpleTransmission</type>
    <joint name="l_arm_wr_r">
      <hardwareInterface>EffortJointInterface</hardwareInterface>
    </joint>
    <actuator name="l_arm_wr_r_motor">
      <hardwareInterface>EffortJointInterface</hardwareInterface>
      <mechanicalReduction>1</mechanicalReduction>
    </actuator>
  </transmission>
  <!-- left wrist roll link -->
  <link name="l_arm_wr_r_link">
    	  <collision>
      	    <origin xyz="0.02 0 0" rpy="0 0 0"/>
      	    <geometry>
              <box size="0.05 0.05 0.11" />
      	    </geometry>
    	  </collision>
    <visual>
      <origin rpy="0 0 0" xyz="0 0 0"/>
      <geometry>
        <mesh filename="package://gogoro_description/meshes/thormang3/robotis_l_arm_wr_r_link.obj" scale="0.001 0.001 0.001"/>
      </geometry>
      <material name="grey"/>
    </visual>
    <inertial>
      <origin rpy="0 0 0" xyz="0.010 0.000 0.002"/>
      <mass value="0.087"/>
      <inertia ixx="1.0" ixy="0.0" ixz="0.0" iyy="1.0" iyz="0.0" izz="1.0"/>
      <!--<inertia ixx="0.00012" ixy="0.0" ixz="0.0" iyy="0.00011" iyz="0.0" izz="0.00003" />-->
    </inertial>
  </link>
  <!-- left wrist yaw joint -->
  <joint name="l_arm_wr_y" type="revolute">
    <axis xyz="0 0 -1"/>
    <origin rpy="0 0 0" xyz="0.039 0.0 0.045"/>
    <parent link="l_arm_wr_r_link"/>
    <child link="l_arm_wr_y_link"/>
    <limit effort="1000" lower="-1.4137166943" upper="1.4137166943" velocity="6.5"/>
    <dynamics damping="0.1" friction="0.0"/>
  </joint>
  <transmission name="l_arm_wr_y_tran">
    <type>transmission_interface/SimpleTransmission</type>
    <joint name="l_arm_wr_y">
      <hardwareInterface>EffortJointInterface</hardwareInterface>
    </joint>
    <actuator name="l_arm_wr_y_motor">
      <hardwareInterface>EffortJointInterface</hardwareInterface>
      <mechanicalReduction>1</mechanicalReduction>
    </actuator>
  </transmission>
  <!-- left wrist yaw link -->
  <link name="l_arm_wr_y_link">
    	  <collision>
      	    <origin xyz="0.03 0 -0.045" rpy="0 0 0"/>
      	    <geometry>
              <box size="0.09 0.1 0.09" />
      	    </geometry>
    	  </collision>
    <visual>
      <origin rpy="0 0 0" xyz="0 0 0"/>
      <geometry>
        <mesh filename="package://gogoro_description/meshes/thormang3/robotis_l_arm_wr_y_link.obj" scale="0.001 0.001 0.001"/>
      </geometry>
      <material name="grey"/>
    </visual>
    <inertial>
      <origin rpy="0 0 0" xyz="0.023 0.001 -0.046"/>
      <mass value="0.768"/>
      <inertia ixx="1.0" ixy="0.0" ixz="0.0" iyy="1.0" iyz="0.0" izz="1.0"/>
      <!--<inertia ixx="0.00059" ixy="-0.00002" ixz="-0.00002" iyy="0.00078" iyz="0.0" izz="0.00078" />-->
    </inertial>
  </link>
  <!-- left wrist pitch joint -->
  <joint name="l_arm_wr_p" type="revolute">
    <axis xyz="0 -1 0"/>
    <origin rpy="0 0 0" xyz="0.045 -0.045 -0.045"/>
    <parent link="l_arm_wr_y_link"/>
    <child link="l_arm_wr_p_link"/>
    <limit effort="1000" lower="-1.4137166943" upper="1.4137166943" velocity="6.5"/>
    <dynamics damping="0.1" friction="0.0"/>
  </joint>
  <transmission name="l_arm_wr_p_tran">
    <type>transmission_interface/SimpleTransmission</type>
    <joint name="l_arm_wr_p">
      <hardwareInterface>EffortJointInterface</hardwareInterface>
    </joint>
    <actuator name="l_arm_wr_p_motor">
      <hardwareInterface>EffortJointInterface</hardwareInterface>
      <mechanicalReduction>1</mechanicalReduction>
    </actuator>
  </transmission>
  <!-- left wrist pitch link -->
  <link name="l_arm_wr_p_link">
    	  <collision>
      	    <origin xyz="0.07 0.045 0" rpy="0 0 0"/>
      	    <geometry>
              <box size="0.07 0.1 0.06" />
      	    </geometry>
    	  </collision>
    <visual>
      <origin rpy="0 0 0" xyz="0 0 0"/>
      <geometry>
        <mesh filename="package://gogoro_description/meshes/thormang3/robotis_l_arm_wr_p_link.obj" scale="0.001 0.001 0.001"/>
      </geometry>
      <material name="grey"/>
    </visual>
    <inertial>
      <origin rpy="0 0 0" xyz="0.065 0.045 0.000"/>
      <mass value="0.565"/>
      <inertia ixx="1.0" ixy="0.0" ixz="0.0" iyy="1.0" iyz="0.0" izz="1.0"/>
      <!--<inertia ixx="0.00047" ixy="-0.00001" ixz="0.0" iyy="0.00042" iyz="0.0" izz="0.00058" />-->
    </inertial>
  </link>
  <!-- left arm gripper joint -->
  <joint name="l_arm_grip" type="revolute">
    <axis xyz="0 0 -1"/>
    <origin rpy="0 0 0.698131700889" xyz="0.0877 0.0583 0.0"/>
    <parent link="l_arm_wr_p_link"/>
    <child link="l_arm_grip_link"/>
    <limit effort="1000" lower="0.0" upper="1.13446401394" velocity="6.5"/>
    <dynamics damping="0.1" friction="0.0"/>
  </joint>
  <transmission name="l_arm_grip_tran">
    <type>transmission_interface/SimpleTransmission</type>
    <joint name="l_arm_grip">
      <hardwareInterface>EffortJointInterface</hardwareInterface>
    </joint>
    <actuator name="l_arm_grip_motor">
      <hardwareInterface>EffortJointInterface</hardwareInterface>
      <mechanicalReduction>1</mechanicalReduction>
    </actuator>
  </transmission>
  <!-- left arm gripper link -->
  <link name="l_arm_grip_link">
    <visual>
      <origin rpy="0 0 0" xyz="0 0 0"/>
      <geometry>
        <mesh filename="package://gogoro_description/meshes/thormang3/robotis_l_arm_grip_link.obj" scale="0.001 0.001 0.001"/>
      </geometry>
      <material name="grey"/>
    </visual>
    <inertial>
      <origin rpy="0 0 0" xyz="0.031 0.014 0.000"/>
      <mass value="0.013"/>
      <inertia ixx="1.0" ixy="0.0" ixz="0.0" iyy="1.0" iyz="0.0" izz="1.0"/>
      <!--<inertia ixx="0.0" ixy="0.0" ixz="0.0" iyy="0.00001" iyz="0.0" izz="0.00001" />-->
    </inertial>
  </link>
  <!-- left arm gripper 1 joint -->
  <joint name="l_arm_grip_1" type="revolute">
    <axis xyz="0 0 1"/>
    <origin rpy="0 0 -0.698131700889" xyz="0.0877 0.0317 0.0"/>
    <parent link="l_arm_wr_p_link"/>
    <child link="l_arm_grip_1_link"/>
    <limit effort="1000" lower="0.0" upper="1.13446401394" velocity="6.5"/>
    <dynamics damping="0.1" friction="0.0"/>
  </joint>
  <transmission name="l_arm_grip_1_tran">
    <type>transmission_interface/SimpleTransmission</type>
    <joint name="l_arm_grip_1">
      <hardwareInterface>EffortJointInterface</hardwareInterface>
    </joint>
    <actuator name="l_arm_grip_1_motor">
      <hardwareInterface>EffortJointInterface</hardwareInterface>
      <mechanicalReduction>1</mechanicalReduction>
    </actuator>
  </transmission>
  <!-- left arm gripper 1 link -->
  <link name="l_arm_grip_1_link">
    <visual>
      <origin rpy="0 0 0" xyz="0 0 0"/>
      <geometry>
        <mesh filename="package://gogoro_description/meshes/thormang3/robotis_l_arm_grip_1_link.obj" scale="0.001 0.001 0.001"/>
      </geometry>
      <material name="grey"/>
    </visual>
    <inertial>
      <origin rpy="0 0 0" xyz="0.031 -0.014 0.000"/>
      <mass value="0.013"/>
      <inertia ixx="1.0" ixy="0.0" ixz="0.0" iyy="1.0" iyz="0.0" izz="1.0"/>
      <!--<inertia ixx="0.0" ixy="0.0" ixz="0.0" iyy="0.00001" iyz="0.0" izz="0.00001" />-->
    </inertial>
  </link>
  <!-- left end effector -->
  <joint name="l_arm_end" type="fixed">
    <origin rpy="0 0 0" xyz="0.145 0.045 0"/>
    <parent link="l_arm_wr_p_link"/>
    <child link="l_arm_end_link"/>
  </joint>
  <!-- left end effector link -->
  <link name="l_arm_end_link">
    <visual>
      <origin rpy="0 0 0" xyz="0 0 0"/>
      <geometry>
        <box size="0.01 0.01 0.01"/>
      </geometry>
      <material name="red"/>
    </visual>
    <inertial>
      <origin rpy="0 0 0" xyz="0.0 0.0 0.0"/>
      <mass value="0.001"/>
      <inertia ixx="1.0" ixy="0.0" ixz="0.0" iyy="1.0" iyz="0.0" izz="1.0"/>
    </inertial>
  </link>
  <!-- right shoulder pitch 1 joint -->
  <joint name="r_arm_sh_p1" type="revolute">
    <axis xyz="0 -1 0"/>
    <origin rpy="0 0 0" xyz="0.0 -0.152 0.16"/>
    <parent link="chest_link"/>
    <child link="r_arm_sh_p1_link"/>
    <limit effort="1000" lower="-1.570796327" upper="1.570796327" velocity="6.5"/>
    <dynamics damping="0.1" friction="0.0"/>
  </joint>
  <transmission name="r_arm_sh_p1_tran">
    <type>transmission_interface/SimpleTransmission</type>
    <joint name="r_arm_sh_p1">
      <hardwareInterface>EffortJointInterface</hardwareInterface>
    </joint>
    <actuator name="r_arm_sh_p1_motor">
      <hardwareInterface>EffortJointInterface</hardwareInterface>
      <mechanicalReduction>1</mechanicalReduction>
    </actuator>
  </transmission>
  <!-- right shoulder pitch 1 link -->
  <link name="r_arm_sh_p1_link">
    	  <collision>
      	    <origin xyz="0 -0.03 -0.01" rpy="0 0 0"/>
      	    <geometry>
              <box size="0.15 0.1 0.09" />
      	    </geometry>
    	  </collision>
    <visual>
      <origin rpy="0 0 0" xyz="0 0 0"/>
      <geometry>
        <mesh filename="package://gogoro_description/meshes/thormang3/robotis_r_arm_sh_p1_link.obj" scale="0.001 0.001 0.001"/>
      </geometry>
      <material name="grey"/>
    </visual>
    <inertial>
      <origin rpy="0 0 0" xyz="-0.003 -0.020 -0.005"/>
      <mass value="0.194"/>
      <inertia ixx="1.0" ixy="0.0" ixz="0.0" iyy="1.0" iyz="0.0" izz="1.0"/>
      <!--<inertia ixx="0.00018" ixy="0.0" ixz="0.0" iyy="0.00058" iyz="-0.00004" izz="0.00057" />-->
    </inertial>
  </link>
  <!-- right shoulder roll joint -->
  <joint name="r_arm_sh_r" type="revolute">
    <axis xyz="-1 0 0"/>
    <origin rpy="0 0 0" xyz="0.057 -0.060 -0.039"/>
    <parent link="r_arm_sh_p1_link"/>
    <child link="r_arm_sh_r_link"/>
    <limit effort="1000" lower="-1.570796327" upper="1.570796327" velocity="6.5"/>
    <dynamics damping="0.1" friction="0.0"/>
  </joint>
  <transmission name="r_arm_sh_r_tran">
    <type>transmission_interface/SimpleTransmission</type>
    <joint name="r_arm_sh_r">
      <hardwareInterface>EffortJointInterface</hardwareInterface>
    </joint>
    <actuator name="r_arm_sh_r_motor">
      <hardwareInterface>EffortJointInterface</hardwareInterface>
      <mechanicalReduction>1</mechanicalReduction>
    </actuator>
  </transmission>
  <!-- right shoulder roll link -->
  <link name="r_arm_sh_r_link">
    	  <collision>
      	    <origin xyz="-0.057 0 0" rpy="0 0 0"/>
      	    <geometry>
              <box size="0.14 0.09 0.09" />
      	    </geometry>
    	  </collision>
    <visual>
      <origin rpy="0 0 0" xyz="0 0 0"/>
      <geometry>
        <mesh filename="package://gogoro_description/meshes/thormang3/robotis_r_arm_sh_r_link.obj" scale="0.001 0.001 0.001"/>
      </geometry>
      <material name="grey"/>
    </visual>
    <inertial>
      <origin rpy="0 0 0" xyz="-0.060 -0.002 0.000"/>
      <mass value="0.875"/>
      <inertia ixx="1.0" ixy="0.0" ixz="0.0" iyy="1.0" iyz="0.0" izz="1.0"/>
      <!--<inertia ixx="0.00043" ixy="0.0" ixz="0.0" iyy="0.00112" iyz="0.0" izz="0.00113" />-->
    </inertial>
  </link>
  <!-- right shoulder pitch 2 joint -->
  <joint name="r_arm_sh_p2" type="revolute">
    <axis xyz="0 -1 0"/>
    <origin rpy="0 0 0" xyz="-0.057 -0.033 0.0"/>
    <parent link="r_arm_sh_r_link"/>
    <child link="r_arm_sh_p2_link"/>
    <limit effort="1000" lower="-1.570796327" upper="1.570796327" velocity="6.5"/>
    <dynamics damping="0.1" friction="0.0"/>
  </joint>
  <transmission name="r_arm_sh_p2_tran">
    <type>transmission_interface/SimpleTransmission</type>
    <joint name="r_arm_sh_p2">
      <hardwareInterface>EffortJointInterface</hardwareInterface>
    </joint>
    <actuator name="r_arm_sh_p2_motor">
      <hardwareInterface>EffortJointInterface</hardwareInterface>
      <mechanicalReduction>1</mechanicalReduction>
    </actuator>
  </transmission>
  <!-- right shoulder pitch2 link -->
  <link name="r_arm_sh_p2_link">
    	  <collision>
      	    <origin xyz="0.01 -0.11 0" rpy="0 0 0"/>
      	    <geometry>
              <box size="0.1 0.24 0.13" />
      	    </geometry>
    	  </collision>
    <visual>
      <origin rpy="0 0 0" xyz="0 0 0"/>
      <geometry>
        <mesh filename="package://gogoro_description/meshes/thormang3/robotis_r_arm_sh_p2_link.obj" scale="0.001 0.001 0.001"/>
      </geometry>
      <material name="grey"/>
    </visual>
    <inertial>
      <origin rpy="0 0 0" xyz="0.000 -0.073 0.000"/>
      <mass value="1.122"/>
      <inertia ixx="1.0" ixy="0.0" ixz="0.0" iyy="1.0" iyz="0.0" izz="1.0"/>
      <!--<inertia ixx="0.00277" ixy="0.00002" ixz="-0.00001" iyy="0.00090" iyz="0.00004" izz="0.00255" />-->
    </inertial>
  </link>
  <!-- right elbow yaw joint -->
  <joint name="r_arm_el_y" type="revolute">
    <axis xyz="0 0 -1"/>
    <origin rpy="0 0 0" xyz="0.030 -0.187 0.057"/>
    <parent link="r_arm_sh_p2_link"/>
    <child link="r_arm_el_y_link"/>
    <limit effort="1000" lower="-1.2566370616" upper="1.2566370616" velocity="6.5"/>
    <dynamics damping="0.1" friction="0.0"/>
  </joint>
  <transmission name="r_arm_el_y_tran">
    <type>transmission_interface/SimpleTransmission</type>
    <joint name="r_arm_el_y">
      <hardwareInterface>EffortJointInterface</hardwareInterface>
    </joint>
    <actuator name="r_arm_el_y_motor">
      <hardwareInterface>EffortJointInterface</hardwareInterface>
      <mechanicalReduction>1</mechanicalReduction>
    </actuator>
  </transmission>
  <!-- right elbow yaw link -->
  <link name="r_arm_el_y_link">
    	  <collision>
      	    <origin xyz="0.08 -0.01 -0.057" rpy="0 0 0"/>
      	    <geometry>
              <box size="0.17 0.1 0.08" />
      	    </geometry>
    	  </collision>
    <visual>
      <origin rpy="0 0 0" xyz="0 0 0"/>
      <geometry>
        <mesh filename="package://gogoro_description/meshes/thormang3/robotis_r_arm_el_y_link.obj" scale="0.001 0.001 0.001"/>
      </geometry>
      <material name="grey"/>
    </visual>
    <inertial>
      <origin rpy="0 0 0" xyz="0.042 -0.012 -0.058"/>
      <mass value="1.357"/>
      <inertia ixx="1.0" ixy="0.0" ixz="0.0" iyy="1.0" iyz="0.0" izz="1.0"/>
      <!--<inertia ixx="0.00152" ixy="0.00100" ixz="-0.00006" iyy="0.00560" iyz="0.00002" izz="0.00528" />-->
    </inertial>
  </link>
  <!-- right wrist roll joint -->
  <joint name="r_arm_wr_r" type="revolute">
    <axis xyz="1 0 0"/>
    <origin rpy="0 0 0" xyz="0.171 -0.030 -0.057"/>
    <parent link="r_arm_el_y_link"/>
    <child link="r_arm_wr_r_link"/>
    <limit effort="1000" lower="-2.8274333886" upper="2.8274333886" velocity="6.5"/>
    <dynamics damping="0.1" friction="0.0"/>
  </joint>
  <transmission name="r_arm_wr_r_tran">
    <type>transmission_interface/SimpleTransmission</type>
    <joint name="r_arm_wr_r">
      <hardwareInterface>EffortJointInterface</hardwareInterface>
    </joint>
    <actuator name="r_arm_wr_r_motor">
      <hardwareInterface>EffortJointInterface</hardwareInterface>
      <mechanicalReduction>1</mechanicalReduction>
    </actuator>
  </transmission>
  <!-- right wrist roll link -->
  <link name="r_arm_wr_r_link">
    	  <collision>
      	    <origin xyz="0.02 0 0" rpy="0 0 0"/>
      	    <geometry>
              <box size="0.05 0.05 0.11" />
      	    </geometry>
    	  </collision>
    <visual>
      <origin rpy="0 0 0" xyz="0 0 0"/>
      <geometry>
        <mesh filename="package://gogoro_description/meshes/thormang3/robotis_r_arm_wr_r_link.obj" scale="0.001 0.001 0.001"/>
      </geometry>
      <material name="grey"/>
    </visual>
    <inertial>
      <origin rpy="0 0 0" xyz="0.010 0.000 -0.002"/>
      <mass value="0.087"/>
      <inertia ixx="1.0" ixy="0.0" ixz="0.0" iyy="1.0" iyz="0.0" izz="1.0"/>
      <!--<inertia ixx="0.00012" ixy="0.0" ixz="0.0" iyy="0.00011" iyz="0.0" izz="0.00003" />-->
    </inertial>
  </link>
  <!-- right wrist yaw joint -->
  <joint name="r_arm_wr_y" type="revolute">
    <axis xyz="0 0 -1"/>
    <origin rpy="0 0 0" xyz="0.039 0.0 0.045"/>
    <parent link="r_arm_wr_r_link"/>
    <child link="r_arm_wr_y_link"/>
    <limit effort="1000" lower="-1.4137166943" upper="1.4137166943" velocity="6.5"/>
    <dynamics damping="0.1" friction="0.0"/>
  </joint>
  <transmission name="r_arm_wr_y_tran">
    <type>transmission_interface/SimpleTransmission</type>
    <joint name="r_arm_wr_y">
      <hardwareInterface>EffortJointInterface</hardwareInterface>
    </joint>
    <actuator name="r_arm_wr_y_motor">
      <hardwareInterface>EffortJointInterface</hardwareInterface>
      <mechanicalReduction>1</mechanicalReduction>
    </actuator>
  </transmission>
  <!-- right wrist yaw link -->
  <link name="r_arm_wr_y_link">
    	  <collision>
      	    <origin xyz="0.03 0 -0.045" rpy="0 0 0"/>
      	    <geometry>
              <box size="0.09 0.1 0.09" />
      	    </geometry>
    	  </collision>
    <visual>
      <origin rpy="0 0 0" xyz="0 0 0"/>
      <geometry>
        <mesh filename="package://gogoro_description/meshes/thormang3/robotis_r_arm_wr_y_link.obj" scale="0.001 0.001 0.001"/>
      </geometry>
      <material name="grey"/>
    </visual>
    <inertial>
      <origin rpy="0 0 0" xyz="0.023 -0.001 -0.046"/>
      <mass value="0.768"/>
      <inertia ixx="1.0" ixy="0.0" ixz="0.0" iyy="1.0" iyz="0.0" izz="1.0"/>
      <!--<inertia ixx="0.00059" ixy="0.00002" ixz="-0.00002" iyy="0.00078" iyz="0.0" izz="0.00078" />-->
    </inertial>
  </link>
  <!-- right wrist pitch joint -->
  <joint name="r_arm_wr_p" type="revolute">
    <axis xyz="0 1 0"/>
    <origin rpy="0 0 0" xyz="0.045 0.045 -0.045"/>
    <parent link="r_arm_wr_y_link"/>
    <child link="r_arm_wr_p_link"/>
    <limit effort="1000" lower="-1.4137166943" upper="1.4137166943" velocity="6.5"/>
    <dynamics damping="0.1" friction="0.0"/>
  </joint>
  <transmission name="r_arm_wr_p_tran">
    <type>transmission_interface/SimpleTransmission</type>
    <joint name="r_arm_wr_p">
      <hardwareInterface>EffortJointInterface</hardwareInterface>
    </joint>
    <actuator name="r_arm_wr_p_motor">
      <hardwareInterface>EffortJointInterface</hardwareInterface>
      <mechanicalReduction>1</mechanicalReduction>
    </actuator>
  </transmission>
  <!-- right wrist pitch link -->
  <link name="r_arm_wr_p_link">
    	  <collision>
      	    <origin xyz="0.07 -0.045 0" rpy="0 0 0"/>
      	    <geometry>
              <box size="0.07 0.1 0.06" />
      	    </geometry>
    	  </collision>
    <visual>
      <origin rpy="0 0 0" xyz="0 0 0"/>
      <geometry>
        <mesh filename="package://gogoro_description/meshes/thormang3/robotis_r_arm_wr_p_link.obj" scale="0.001 0.001 0.001"/>
      </geometry>
      <material name="grey"/>
    </visual>
    <inertial>
      <origin rpy="0 0 0" xyz="0.065 -0.045 0.000"/>
      <mass value="0.565"/>
      <inertia ixx="1.0" ixy="0.0" ixz="0.0" iyy="1.0" iyz="0.0" izz="1.0"/>
      <!--<inertia ixx="0.00047" ixy="0.00001" ixz="0.0" iyy="0.00042" iyz="0.0" izz="0.00058" />-->
    </inertial>
  </link>
  <!-- right arm gripper joint -->
  <joint name="r_arm_grip" type="revolute">
    <axis xyz="0 0 1"/>
    <origin rpy="0 0 -0.698131700889" xyz="0.0877 -0.0583 0.0"/>
    <parent link="r_arm_wr_p_link"/>
    <child link="r_arm_grip_link"/>
    <limit effort="1000" lower="0.0" upper="1.13446401394" velocity="6.5"/>
    <dynamics damping="0.1" friction="0.0"/>
  </joint>
  <transmission name="r_arm_grip_tran">
    <type>transmission_interface/SimpleTransmission</type>
    <joint name="r_arm_grip">
      <hardwareInterface>EffortJointInterface</hardwareInterface>
    </joint>
    <actuator name="r_arm_grip_motor">
      <hardwareInterface>EffortJointInterface</hardwareInterface>
      <mechanicalReduction>1</mechanicalReduction>
    </actuator>
  </transmission>
  <!-- right arm gripper link -->
  <link name="r_arm_grip_link">
    <visual>
      <origin rpy="0 0 0" xyz="0 0 0"/>
      <geometry>
        <mesh filename="package://gogoro_description/meshes/thormang3/robotis_r_arm_grip_1_link.obj" scale="0.001 0.001 0.001"/>
      </geometry>
      <material name="grey"/>
    </visual>
    <inertial>
      <origin rpy="0 0 0" xyz="0.031 -0.014 0.000"/>
      <mass value="0.013"/>
      <inertia ixx="1.0" ixy="0.0" ixz="0.0" iyy="1.0" iyz="0.0" izz="1.0"/>
      <!--<inertia ixx="0.0" ixy="0.0" ixz="0.0" iyy="0.00001" iyz="0.0" izz="0.00001" />-->
    </inertial>
  </link>
  <!-- right arm gripper 1 joint -->
  <joint name="r_arm_grip_1" type="revolute">
    <axis xyz="0 0 -1"/>
    <origin rpy="0 0 0.698131700889" xyz="0.0877 -0.0317 0.0"/>
    <parent link="r_arm_wr_p_link"/>
    <child link="r_arm_grip_1_link"/>
    <limit effort="1000" lower="0.0" upper="1.13446401394" velocity="6.5"/>
    <dynamics damping="0.1" friction="0.0"/>
  </joint>
  <transmission name="r_arm_grip_1_tran">
    <type>transmission_interface/SimpleTransmission</type>
    <joint name="r_arm_grip_1">
      <hardwareInterface>EffortJointInterface</hardwareInterface>
    </joint>
    <actuator name="r_arm_grip_1_motor">
      <hardwareInterface>EffortJointInterface</hardwareInterface>
      <mechanicalReduction>1</mechanicalReduction>
    </actuator>
  </transmission>
  <!-- right arm gripper link -->
  <link name="r_arm_grip_1_link">
    <visual>
      <origin rpy="0 0 0" xyz="0 0 0"/>
      <geometry>
        <mesh filename="package://gogoro_description/meshes/thormang3/robotis_r_arm_grip_link.obj" scale="0.001 0.001 0.001"/>
      </geometry>
      <material name="grey"/>
    </visual>
    <inertial>
      <origin rpy="0 0 0" xyz="0.031 0.014 0.000"/>
      <mass value="0.013"/>
      <inertia ixx="1.0" ixy="0.0" ixz="0.0" iyy="1.0" iyz="0.0" izz="1.0"/>
      <!--<inertia ixx="0.0" ixy="0.0" ixz="0.0" iyy="0.00001" iyz="0.0" izz="0.00001" />-->
    </inertial>
  </link>
  <!-- right end effector -->
  <joint name="r_arm_end" type="fixed">
    <origin rpy="0 0 0" xyz="0.145 -0.045 0"/>
    <parent link="r_arm_wr_p_link"/>
    <child link="r_arm_end_link"/>
  </joint>
  <!-- right end effector link -->
  <link name="r_arm_end_link">
    <visual>
      <origin rpy="0 0 0" xyz="0 0 0"/>
      <geometry>
        <box size="0.01 0.01 0.01"/>
      </geometry>
      <material name="red"/>
    </visual>
    <inertial>
      <origin rpy="0 0 0" xyz="0.0 0.0 0.0"/>
      <mass value="0.001"/>
      <inertia ixx="1.0" ixy="0.0" ixz="0.0" iyy="1.0" iyz="0.0" izz="1.0"/>
    </inertial>
  </link>
  <!-- left hip yaw joint -->
  <joint name="l_leg_hip_y" type="revolute">
    <axis xyz="0 0 -1"/>
    <origin rpy="0 0 0" xyz="0.0 0.093 -0.018"/>
    <parent link="pelvis_link"/>
    <child link="l_leg_hip_y_link"/>
    <limit effort="1000" lower="-1.4137166943" upper="1.4137166943" velocity="6.5"/>
    <dynamics damping="0.1" friction="0.0"/>
  </joint>
  <transmission name="l_leg_hip_y_tran">
    <type>transmission_interface/SimpleTransmission</type>
    <joint name="l_leg_hip_y">
      <hardwareInterface>EffortJointInterface</hardwareInterface>
    </joint>
    <actuator name="l_leg_hip_y_motor">
      <hardwareInterface>EffortJointInterface</hardwareInterface>
      <mechanicalReduction>1</mechanicalReduction>
    </actuator>
  </transmission>
  <!-- left hip yaw link -->
  <link name="l_leg_hip_y_link">
      <!--
    	  <collision>
      	    <origin xyz="-0.01 0 -0.05" rpy="0 0 0"/>
      	    <geometry>
              <box size="0.17 0.07 0.1" />
      	    </geometry>
    	  </collision>
       -->
    <visual>
      <origin rpy="0 0 0" xyz="0 0 0"/>
      <geometry>
        <mesh filename="package://gogoro_description/meshes/thormang3/robotis_l_leg_hip_y_link.obj" scale="0.001 0.001 0.001"/>
      </geometry>
      <material name="grey"/>
    </visual>
    <inertial>
      <origin rpy="0 0 0" xyz="0.012 0.000 -0.025"/>
      <mass value="0.243"/>
      <inertia ixx="1.0" ixy="0.0" ixz="0.0" iyy="1.0" iyz="0.0" izz="1.0"/>
      <!-- <inertia ixx="0.00024" ixy="0.0" ixz="0.0" iyy="0.00101" iyz="0.0" izz="0.00092" /> -->
    </inertial>
  </link>
  <!-- left hip roll joint -->
  <joint name="l_leg_hip_r" type="revolute">
    <axis xyz="-1 0 0"/>
    <origin rpy="0 0 0" xyz="0.057 0.0 -0.075"/>
    <parent link="l_leg_hip_y_link"/>
    <child link="l_leg_hip_r_link"/>
    <limit effort="1000" lower="-0.6283185308" upper="0.9424777962" velocity="6.5"/>
    <dynamics damping="0.1" friction="0.0"/>
  </joint>
  <transmission name="l_leg_hip_r_tran">
    <type>transmission_interface/SimpleTransmission</type>
    <joint name="l_leg_hip_r">
      <hardwareInterface>EffortJointInterface</hardwareInterface>
    </joint>
    <actuator name="l_leg_hip_r_motor">
      <hardwareInterface>EffortJointInterface</hardwareInterface>
      <mechanicalReduction>1</mechanicalReduction>
    </actuator>
  </transmission>
  <!-- left hip roll link -->
  <link name="l_leg_hip_r_link">
      <!--
    	  <collision>
      	    <origin xyz="-0.057 0 0" rpy="0 0 0"/>
      	    <geometry>
              <box size="0.01 0.01 0.01" />
      	    </geometry>
    	  </collision>
       -->
    <visual>
      <origin rpy="0 0 0" xyz="0 0 0"/>
      <geometry>
        <mesh filename="package://gogoro_description/meshes/thormang3/robotis_l_leg_hip_r_link.obj" scale="0.001 0.001 0.001"/>
      </geometry>
      <material name="grey"/>
    </visual>
    <inertial>
      <origin rpy="0 0 0" xyz="-0.068 0.000 0.000"/>
      <mass value="1.045"/>
      <inertia ixx="1.0" ixy="0.0" ixz="0.0" iyy="1.0" iyz="0.0" izz="1.0"/>
      <!-- <inertia ixx="0.00056" ixy="0.0" ixz="0.0" iyy="0.00168" iyz="0.0" izz="0.00171" /> -->
    </inertial>
  </link>
  <!-- left hip pitch joint -->
  <joint name="l_leg_hip_p" type="revolute">
    <axis xyz="0 1 0"/>
    <origin rpy="0 0 0" xyz="-0.057 0.033 0.0"/>
    <parent link="l_leg_hip_r_link"/>
    <child link="l_leg_hip_p_link"/>
    <limit effort="1000" lower="-1.2566370616" upper="1.2566370616" velocity="6.5"/>
    <dynamics damping="0.1" friction="0.0"/>
  </joint>
  <transmission name="l_leg_hip_p_tran">
    <type>transmission_interface/SimpleTransmission</type>
    <joint name="l_leg_hip_p">
      <hardwareInterface>EffortJointInterface</hardwareInterface>
    </joint>
    <actuator name="l_leg_hip_p_motor">
      <hardwareInterface>EffortJointInterface</hardwareInterface>
      <mechanicalReduction>1</mechanicalReduction>
    </actuator>
  </transmission>
  <!-- left hip pitch link -->
  <link name="l_leg_hip_p_link">
      <!--
    	  <collision>
      	    <origin xyz="0 -0.005 -0.145" rpy="0 0 0"/>
      	    <geometry>
              <box size="0.11 0.16 0.33" />
      	    </geometry>
    	  </collision>
       -->
    <visual>
      <origin rpy="0 0 0" xyz="0 0 0"/>
      <geometry>
        <mesh filename="package://gogoro_description/meshes/thormang3/robotis_l_leg_hip_p_link.obj" scale="0.001 0.001 0.001"/>
      </geometry>
      <material name="grey"/>
    </visual>
    <inertial>
      <origin rpy="0 0 0" xyz="0.022 -0.007 -0.168"/>
      <mass value="3.095"/>
      <inertia ixx="1.0" ixy="0.0" ixz="0.0" iyy="1.0" iyz="0.0" izz="1.0"/>
      <!-- <inertia ixx="0.04328" ixy="0.00028" ixz="0.00288" iyy="0.04042" iyz="-0.00202" izz="0.00560" /> -->
    </inertial>
  </link>
  <!-- left knee pitch joint -->
  <joint name="l_leg_kn_p" type="revolute">
    <axis xyz="0 1 0"/>
    <origin rpy="0 0 0" xyz="0.0 0.06 -0.3"/>
    <parent link="l_leg_hip_p_link"/>
    <child link="l_leg_kn_p_link"/>
    <limit effort="1000" lower="-0.3141592654" upper="2.1991148578" velocity="6.5"/>
    <dynamics damping="0.1" friction="0.0"/>
  </joint>
  <transmission name="l_leg_kn_p_tran">
    <type>transmission_interface/SimpleTransmission</type>
    <joint name="l_leg_kn_p">
      <hardwareInterface>EffortJointInterface</hardwareInterface>
    </joint>
    <actuator name="l_leg_kn_p_motor">
      <hardwareInterface>EffortJointInterface</hardwareInterface>
      <mechanicalReduction>1</mechanicalReduction>
    </actuator>
  </transmission>
  <!-- left knee pitch link -->
  <link name="l_leg_kn_p_link">
      <!--
    	  <collision>
      	    <origin xyz="0.01 -0.065 -0.145" rpy="0 0 0"/>
      	    <geometry>
              <box size="0.11 0.16 0.33" />
      	    </geometry>
    	  </collision>
       -->
    <visual>
      <origin rpy="0 0 0" xyz="0 0 0"/>
      <geometry>
        <mesh filename="package://gogoro_description/meshes/thormang3/robotis_l_leg_kn_p_link.obj" scale="0.001 0.001 0.001"/>
      </geometry>
      <material name="grey"/>
    </visual>
    <inertial>
      <origin rpy="0 0 0" xyz="-0.002 -0.066 -0.183"/>
      <mass value="2.401"/>
      <inertia ixx="1.0" ixy="0.0" ixz="0.0" iyy="1.0" iyz="0.0" izz="1.0"/>
      <!-- <inertia ixx="0.01971" ixy="0.00031" ixz="-0.00294" iyy="0.01687" iyz="0.00140" izz="0.00574" /> -->
    </inertial>
  </link>
  <!-- left ankle pitch joint -->
  <joint name="l_leg_an_p" type="revolute">
    <axis xyz="0 -1 0"/>
    <origin rpy="0 0 0" xyz="-0.0 -0.06 -0.3"/>
    <parent link="l_leg_kn_p_link"/>
    <child link="l_leg_an_p_link"/>
    <limit effort="1000" lower="-1.4137166943" upper="1.4137166943" velocity="6.5"/>
    <dynamics damping="0.1" friction="0.0"/>
  </joint>
  <transmission name="l_leg_an_p_tran">
    <type>transmission_interface/SimpleTransmission</type>
    <joint name="l_leg_an_p">
      <hardwareInterface>EffortJointInterface</hardwareInterface>
    </joint>
    <actuator name="l_leg_an_p_motor">
      <hardwareInterface>EffortJointInterface</hardwareInterface>
      <mechanicalReduction>1</mechanicalReduction>
    </actuator>
  </transmission>
  <!-- left ankle pitch link -->
  <link name="l_leg_an_p_link">
      <!--
    	  <collision>
      	    <origin xyz="0 0 0" rpy="0 0 0"/>
      	    <geometry>
              <box size="0.01 0.01 0.01" />
      	    </geometry>
    	  </collision>
       -->
    <visual>
      <origin rpy="0 0 0" xyz="0 0 0"/>
      <geometry>
        <mesh filename="package://gogoro_description/meshes/thormang3/robotis_l_leg_an_p_link.obj" scale="0.001 0.001 0.001"/>
      </geometry>
      <material name="grey"/>
    </visual>
    <inertial>
      <origin rpy="0 0 0" xyz="-0.011 -0.033 0.000"/>
      <mass value="1.045"/>
      <inertia ixx="1.0" ixy="0.0" ixz="0.0" iyy="1.0" iyz="0.0" izz="1.0"/>
      <!-- <inertia ixx="0.00056" ixy="0.0" ixz="0.0" iyy="0.00168" iyz="0.0" izz="0.00171" /> -->
    </inertial>
  </link>
  <!-- left ankle roll joint -->
  <joint name="l_leg_an_r" type="revolute">
    <axis xyz="1 0 0"/>
    <origin rpy="0 0 0" xyz="0.057 -0.033 0.0"/>
    <parent link="l_leg_an_p_link"/>
    <child link="l_leg_an_r_link"/>
    <limit effort="1000" lower="-1.570796327" upper="1.2566370616" velocity="6.5"/>
    <dynamics damping="0.1" friction="0.0"/>
  </joint>
  <transmission name="l_leg_an_r_tran">
    <type>transmission_interface/SimpleTransmission</type>
    <joint name="l_leg_an_r">
      <hardwareInterface>EffortJointInterface</hardwareInterface>
    </joint>
    <actuator name="l_leg_an_r_motor">
      <hardwareInterface>EffortJointInterface</hardwareInterface>
      <mechanicalReduction>1</mechanicalReduction>
    </actuator>
  </transmission>
  <!-- left ankle roll link -->
  <link name="l_leg_an_r_link">
      <!--
    	  <collision>
      	    <origin xyz="-0.067 0 -0.02" rpy="0 0 0"/>
      	    <geometry>
              <box size="0.17 0.06 0.12" />
      	    </geometry>
    	  </collision>
       -->
    <visual>
      <origin rpy="0 0 0" xyz="0 0 0"/>
      <geometry>
        <mesh filename="package://gogoro_description/meshes/thormang3/robotis_l_leg_an_r_link.obj" scale="0.001 0.001 0.001"/>
      </geometry>
      <material name="grey"/>
    </visual>
    <inertial>
      <origin rpy="0 0 0" xyz="-0.070 0.000 -0.048"/>
      <mass value="0.223"/>
      <inertia ixx="1.0" ixy="0.0" ixz="0.0" iyy="1.0" iyz="0.0" izz="1.0"/>
      <!-- <inertia ixx="0.00022" ixy="0.0" ixz="-0.00001" iyy="0.00099" iyz="0.0" izz="0.00091" /> -->
    </inertial>
  </link>
  <!-- left ft joint -->
  <joint name="l_leg_ft" type="fixed">
    <origin rpy="0 0 0" xyz="-0.057 0.0 -0.087"/>
    <parent link="l_leg_an_r_link"/>
    <child link="l_leg_foot_link"/>
  </joint>
  <!-- left foot link -->
  <link name="l_leg_foot_link">
      <!--
    	  <collision>
      	    <origin xyz="0 0.014 -0.02" rpy="0 0 0"/>
      	    <geometry>
              <box size="0.22 0.15 0.015" />
      	    </geometry>
    	  </collision>
       -->
    <visual>
      <origin rpy="0 0 0" xyz="0 0 0"/>
      <geometry>
        <mesh filename="package://gogoro_description/meshes/thormang3/robotis_l_leg_foot.obj" scale="0.001 0.001 0.001"/>
      </geometry>
      <material name="grey"/>
    </visual>
    <inertial>
      <origin rpy="0 0 0" xyz="0.000 0.009 -0.013"/>
      <mass value="1.689"/>
      <inertia ixx="1.0" ixy="0.0" ixz="0.0" iyy="1.0" iyz="0.0" izz="1.0"/>
      <!-- <inertia ixx="0.00219" ixy="0.0" ixz="0.0" iyy="0.00433" iyz="0.00011" izz="0.00609" /> -->
    </inertial>
  </link>
  <!-- left ft fixed joint -->
  <joint name="l_leg_ft_fixed" type="fixed">
    <origin rpy="3.141592654 0 0" xyz="0.0 0.0 0.0"/>
    <parent link="l_leg_foot_link"/>
    <child link="l_foot_ft_link"/>
  </joint>
  <!-- left foot ft link -->
  <link name="l_foot_ft_link">
        </link>
  <!-- right hip yaw joint -->
  <joint name="r_leg_hip_y" type="revolute">
    <axis xyz="0 0 -1"/>
    <origin rpy="0 0 0" xyz="0.0 -0.093 -0.018"/>
    <parent link="pelvis_link"/>
    <child link="r_leg_hip_y_link"/>
    <limit effort="1000" lower="-1.4137166943" upper="1.4137166943" velocity="6.5"/>
    <dynamics damping="0.1" friction="0.0"/>
  </joint>
  <transmission name="r_leg_hip_y_tran">
    <type>transmission_interface/SimpleTransmission</type>
    <joint name="r_leg_hip_y">
      <hardwareInterface>EffortJointInterface</hardwareInterface>
    </joint>
    <actuator name="r_leg_hip_y_motor">
      <hardwareInterface>EffortJointInterface</hardwareInterface>
      <mechanicalReduction>1</mechanicalReduction>
    </actuator>
  </transmission>
  <!-- right hip yaw link -->
  <link name="r_leg_hip_y_link">
      <!--
    	  <collision>
      	    <origin xyz="-0.01 0 -0.05" rpy="0 0 0"/>
      	    <geometry>
              <box size="0.17 0.07 0.1" />
      	    </geometry>
    	  </collision>
       -->
    <visual>
      <origin rpy="0 0 0" xyz="0 0 0"/>
      <geometry>
        <mesh filename="package://gogoro_description/meshes/thormang3/robotis_r_leg_hip_y_link.obj" scale="0.001 0.001 0.001"/>
      </geometry>
      <material name="grey"/>
    </visual>
    <inertial>
      <origin rpy="0 0 0" xyz="-0.012 0.000 -0.025"/>
      <mass value="0.243"/>
      <inertia ixx="1.0" ixy="0.0" ixz="0.0" iyy="1.0" iyz="0.0" izz="1.0"/>
      <!-- <inertia ixx="0.00024" ixy="0.0" ixz="0.0" iyy="0.00101" iyz="0.0" izz="0.00092" /> -->
    </inertial>
  </link>
  <!-- right hip roll joint -->
  <joint name="r_leg_hip_r" type="revolute">
    <axis xyz="-1 0 0"/>
    <origin rpy="0 0 0" xyz="0.057 0.0 -0.075"/>
    <parent link="r_leg_hip_y_link"/>
    <child link="r_leg_hip_r_link"/>
    <limit effort="1000" lower="-0.9424777962" upper="0.6283185308" velocity="6.5"/>
    <dynamics damping="0.1" friction="0.0"/>
  </joint>
  <transmission name="r_leg_hip_r_tran">
    <type>transmission_interface/SimpleTransmission</type>
    <joint name="r_leg_hip_r">
      <hardwareInterface>EffortJointInterface</hardwareInterface>
    </joint>
    <actuator name="r_leg_hip_r_motor">
      <hardwareInterface>EffortJointInterface</hardwareInterface>
      <mechanicalReduction>1</mechanicalReduction>
    </actuator>
  </transmission>
  <!-- right hip roll link -->
  <link name="r_leg_hip_r_link">
      <!--
    	  <collision>
      	    <origin xyz="0 0 0" rpy="0 0 0"/>
      	    <geometry>
              <box size="0.01 0.01 0.01" />
      	    </geometry>
    	  </collision>
       -->
    <visual>
      <origin rpy="0 0 0" xyz="0 0 0"/>
      <geometry>
        <mesh filename="package://gogoro_description/meshes/thormang3/robotis_r_leg_hip_r_link.obj" scale="0.001 0.001 0.001"/>
      </geometry>
      <material name="grey"/>
    </visual>
    <inertial>
      <origin rpy="0 0 0" xyz="-0.068 0.000 0.000"/>
      <mass value="1.045"/>
      <inertia ixx="1.0" ixy="0.0" ixz="0.0" iyy="1.0" iyz="0.0" izz="1.0"/>
      <!-- <inertia ixx="0.00056" ixy="0.0" ixz="0.0" iyy="0.00168" iyz="0.0" izz="0.00171" /> -->
    </inertial>
  </link>
  <!-- right hip pitch joint -->
  <joint name="r_leg_hip_p" type="revolute">
    <axis xyz="0 -1 0"/>
    <origin rpy="0 0 0" xyz="-0.057 -0.033 0.0"/>
    <parent link="r_leg_hip_r_link"/>
    <child link="r_leg_hip_p_link"/>
    <limit effort="1000" lower="-1.2566370616" upper="1.2566370616" velocity="6.5"/>
    <dynamics damping="0.1" friction="0.0"/>
  </joint>
  <transmission name="r_leg_hip_p_tran">
    <type>transmission_interface/SimpleTransmission</type>
    <joint name="r_leg_hip_p">
      <hardwareInterface>EffortJointInterface</hardwareInterface>
    </joint>
    <actuator name="r_leg_hip_p_motor">
      <hardwareInterface>EffortJointInterface</hardwareInterface>
      <mechanicalReduction>1</mechanicalReduction>
    </actuator>
  </transmission>
  <!-- right hip pitch link -->
  <link name="r_leg_hip_p_link">
      <!--
    	  <collision>
      	    <origin xyz="0 0.005 -0.145" rpy="0 0 0"/>
      	    <geometry>
              <box size="0.11 0.16 0.33" />
      	    </geometry>
    	  </collision>
       -->
    <visual>
      <origin rpy="0 0 0" xyz="0 0 0"/>
      <geometry>
        <mesh filename="package://gogoro_description/meshes/thormang3/robotis_r_leg_hip_p_link.obj" scale="0.001 0.001 0.001"/>
      </geometry>
      <material name="grey"/>
    </visual>
    <inertial>
      <origin rpy="0 0 0" xyz="0.022 0.007 -0.168"/>
      <mass value="3.095"/>
      <inertia ixx="1.0" ixy="0.0" ixz="0.0" iyy="1.0" iyz="0.0" izz="1.0"/>
      <!-- <inertia ixx="0.04328" ixy="-0.00027" ixz="0.00286" iyy="0.04042" iyz="-0.00202" izz="0.00560" /> -->
    </inertial>
  </link>
  <!-- right knee pitch joint -->
  <joint name="r_leg_kn_p" type="revolute">
    <axis xyz="0 -1 0"/>
    <origin rpy="0 0 0" xyz="0.0 -0.06 -0.3"/>
    <parent link="r_leg_hip_p_link"/>
    <child link="r_leg_kn_p_link"/>
    <limit effort="1000" lower="-2.1991148578" upper="0.3141592654" velocity="6.5"/>
    <dynamics damping="0.1" friction="0.0"/>
  </joint>
  <transmission name="r_leg_kn_p_tran">
    <type>transmission_interface/SimpleTransmission</type>
    <joint name="r_leg_kn_p">
      <hardwareInterface>EffortJointInterface</hardwareInterface>
    </joint>
    <actuator name="r_leg_kn_p_motor">
      <hardwareInterface>EffortJointInterface</hardwareInterface>
      <mechanicalReduction>1</mechanicalReduction>
    </actuator>
  </transmission>
  <!-- right knee pitch link -->
  <link name="r_leg_kn_p_link">
      <!--
    	  <collision>
      	    <origin xyz="0.01 0.065 -0.145" rpy="0 0 0"/>
      	    <geometry>
              <box size="0.11 0.16 0.33" />
      	    </geometry>
    	  </collision>
       -->
    <visual>
      <origin rpy="0 0 0" xyz="0 0 0"/>
      <geometry>
        <mesh filename="package://gogoro_description/meshes/thormang3/robotis_r_leg_kn_p_link.obj" scale="0.001 0.001 0.001"/>
      </geometry>
      <material name="grey"/>
    </visual>
    <inertial>
      <origin rpy="0 0 0" xyz="-0.002 0.066 -0.183"/>
      <mass value="2.401"/>
      <inertia ixx="1.0" ixy="0.0" ixz="0.0" iyy="1.0" iyz="0.0" izz="1.0"/>
      <!-- <inertia ixx="0.01971" ixy="-0.00031" ixz="-0.00294" iyy="0.01687" iyz="-0.00140" izz="0.00574" /> -->
    </inertial>
  </link>
  <!-- right ankle pitch joint -->
  <joint name="r_leg_an_p" type="revolute">
    <axis xyz="0 1 0"/>
    <origin rpy="0 0 0" xyz="-0.0 0.06 -0.3"/>
    <parent link="r_leg_kn_p_link"/>
    <child link="r_leg_an_p_link"/>
    <limit effort="1000" lower="-1.4137166943" upper="1.4137166943" velocity="6.5"/>
    <dynamics damping="0.1" friction="0.0"/>
  </joint>
  <transmission name="r_leg_an_p_tran">
    <type>transmission_interface/SimpleTransmission</type>
    <joint name="r_leg_an_p">
      <hardwareInterface>EffortJointInterface</hardwareInterface>
    </joint>
    <actuator name="r_leg_an_p_motor">
      <hardwareInterface>EffortJointInterface</hardwareInterface>
      <mechanicalReduction>1</mechanicalReduction>
    </actuator>
  </transmission>
  <!-- right ankle pitch link -->
  <link name="r_leg_an_p_link">
      <!--
    	  <collision>
      	    <origin xyz="0 0 0" rpy="0 0 0"/>
      	    <geometry>
              <box size="0.01 0.01 0.01" />
      	    </geometry>
    	  </collision>
       -->
    <visual>
      <origin rpy="0 0 0" xyz="0 0 0"/>
      <geometry>
        <mesh filename="package://gogoro_description/meshes/thormang3/robotis_r_leg_an_p_link.obj" scale="0.001 0.001 0.001"/>
      </geometry>
      <material name="grey"/>
    </visual>
    <inertial>
      <origin rpy="0 0 0" xyz="-0.011 0.033 0.000"/>
      <mass value="1.045"/>
      <inertia ixx="1.0" ixy="0.0" ixz="0.0" iyy="1.0" iyz="0.0" izz="1.0"/>
      <!-- <inertia ixx="0.00056" ixy="0.0" ixz="0.0" iyy="0.00168" iyz="0.0" izz="0.00171" /> -->
    </inertial>
  </link>
  <!-- right ankle roll joint -->
  <joint name="r_leg_an_r" type="revolute">
    <axis xyz="1 0 0"/>
    <origin rpy="0 0 0" xyz="0.057 0.033 0.0"/>
    <parent link="r_leg_an_p_link"/>
    <child link="r_leg_an_r_link"/>
    <limit effort="1000" lower="-1.4137166943" upper="1.4137166943" velocity="6.5"/>
    <dynamics damping="0.1" friction="0.0"/>
  </joint>
  <transmission name="r_leg_an_r_tran">
    <type>transmission_interface/SimpleTransmission</type>
    <joint name="r_leg_an_r">
      <hardwareInterface>EffortJointInterface</hardwareInterface>
    </joint>
    <actuator name="r_leg_an_r_motor">
      <hardwareInterface>EffortJointInterface</hardwareInterface>
      <mechanicalReduction>1</mechanicalReduction>
    </actuator>
  </transmission>
  <!-- right ankle roll link -->
  <link name="r_leg_an_r_link">
      <!--
    	  <collision>
      	    <origin xyz="-0.067 0 -0.02" rpy="0 0 0"/>
      	    <geometry>
              <box size="0.17 0.06 0.12" />
      	    </geometry>
    	  </collision>
       -->
    <visual>
      <origin rpy="0 0 0" xyz="0 0 0"/>
      <geometry>
        <mesh filename="package://gogoro_description/meshes/thormang3/robotis_r_leg_an_r_link.obj" scale="0.001 0.001 0.001"/>
      </geometry>
      <material name="grey"/>
    </visual>
    <inertial>
      <origin rpy="0 0 0" xyz="-0.070 0.000 -0.048"/>
      <mass value="0.223"/>
      <inertia ixx="1.0" ixy="0.0" ixz="0.0" iyy="1.0" iyz="0.0" izz="1.0"/>
      <!-- <inertia ixx="0.00022" ixy="0.0" ixz="-0.00001" iyy="0.00099" iyz="0.0" izz="0.00091" /> -->
    </inertial>
  </link>
  <!-- right ft joint -->
  <joint name="r_leg_ft" type="fixed">
    <origin rpy="0 0 0" xyz="-0.057 0.0 -0.087"/>
    <parent link="r_leg_an_r_link"/>
    <child link="r_leg_foot_link"/>
  </joint>
  <!-- right foot link -->
  <link name="r_leg_foot_link">
      <!--
    	  <collision>
      	    <origin xyz="0 -0.014 -0.02" rpy="0 0 0"/>
      	    <geometry>
              <box size="0.22 0.15 0.015" />
      	    </geometry>
    	  </collision>
       -->
    <visual>
      <origin rpy="0 0 0" xyz="0 0 0"/>
      <geometry>
        <mesh filename="package://gogoro_description/meshes/thormang3/robotis_r_leg_foot.obj" scale="0.001 0.001 0.001"/>
      </geometry>
      <material name="grey"/>
    </visual>
    <inertial>
      <origin rpy="0 0 0" xyz="0.000 -0.009 -0.013"/>
      <mass value="1.689"/>
      <inertia ixx="1.0" ixy="0.0" ixz="0.0" iyy="1.0" iyz="0.0" izz="1.0"/>
      <!-- <inertia ixx="0.00219" ixy="0.0" ixz="0.0" iyy="0.00433" iyz="-0.00011" izz="0.00609" /> -->
    </inertial>
  </link>
  <!-- right ft fixed joint -->
  <joint name="r_leg_ft_fixed" type="fixed">
    <origin rpy="3.141592654 0 0" xyz="0.0 0.0 0.0"/>
    <parent link="r_leg_foot_link"/>
    <child link="r_foot_ft_link"/>
  </joint>
  <!-- right foot ft link -->
  <link name="r_foot_ft_link">
        </link>
  <!-- head yaw joint -->
  <joint name="head_y" type="revolute">
    <axis xyz="0 0 1"/>
    <origin rpy="0 0 0" xyz="0.0 0.0 0.229"/>
    <parent link="chest_link"/>
    <child link="head_y_link"/>
    <limit effort="1000" lower="-1.570796327" upper="1.570796327" velocity="6.5"/>
    <dynamics damping="0.1" friction="0.0"/>
  </joint>
  <transmission name="head_y_tran">
    <type>transmission_interface/SimpleTransmission</type>
    <joint name="head_y">
      <hardwareInterface>EffortJointInterface</hardwareInterface>
    </joint>
    <actuator name="head_y_motor">
      <hardwareInterface>EffortJointInterface</hardwareInterface>
      <mechanicalReduction>1</mechanicalReduction>
    </actuator>
  </transmission>
  <!-- head yaw link -->
  <link name="head_y_link">
    	  <collision>
      	    <origin xyz="0 0 0" rpy="0 0 0"/>
      	    <geometry>
              <box size="0.07 0.1 0.1" />
      	    </geometry>
    	  </collision>
    <visual>
      <origin rpy="0 0 0" xyz="0 0 0"/>
      <geometry>
        <mesh filename="package://gogoro_description/meshes/thormang3/robotis_head_y_link.obj" scale="0.001 0.001 0.001"/>
      </geometry>
      <material name="grey"/>
    </visual>
    <inertial>
      <origin rpy="0 0 0" xyz="0.0 0.0 0.0"/>
      <mass value="1.0"/>
      <inertia ixx="1.0" ixy="0.0" ixz="0.0" iyy="1.0" iyz="0.0" izz="1.0"/>
    </inertial>
  </link>
  <!-- head pitch joint -->
  <joint name="head_p" type="revolute">
    <axis xyz="0 1 0"/>
    <origin rpy="0 0 0" xyz="0.0 -0.045 0.039"/>
    <parent link="head_y_link"/>
    <child link="head_p_link"/>
    <limit effort="1000" lower="-1.570796327" upper="1.570796327" velocity="6.5"/>
    <dynamics damping="0.1" friction="0.0"/>
  </joint>
  <transmission name="head_p_tran">
    <type>transmission_interface/SimpleTransmission</type>
    <joint name="head_p">
      <hardwareInterface>EffortJointInterface</hardwareInterface>
    </joint>
    <actuator name="head_p_motor">
      <hardwareInterface>EffortJointInterface</hardwareInterface>
      <mechanicalReduction>1</mechanicalReduction>
    </actuator>
  </transmission>
  <!-- head pitch link -->
  <link name="head_p_link">
    	  <collision>
      	    <origin xyz="0.01 0.045 0.06" rpy="0 0 0"/>
      	    <geometry>
              <box size="0.13 0.15 0.15" />
      	    </geometry>
    	  </collision>
    <visual>
      <origin rpy="0 0 0" xyz="0 0 0"/>
      <geometry>
        <mesh filename="package://gogoro_description/meshes/thormang3/robotis_head_p_link.obj" scale="0.001 0.001 0.001"/>
      </geometry>
      <material name="grey"/>
    </visual>
    <inertial>
      <origin rpy="0 0 0" xyz="0.0 0.0 0.0"/>
      <mass value="1.0"/>
      <inertia ixx="1.0" ixy="0.0" ixz="0.0" iyy="1.0" iyz="0.0" izz="1.0"/>
    </inertial>
  </link>
  <!-- camera joint -->
  <joint name="cam" type="fixed">
    <!--<origin xyz="0.0682 0.045 0.056" rpy="${-pi*0.5} 0 ${-pi*0.5}"/> -->
    <origin rpy="0 0 0" xyz="0.0682 0.045 0.056"/>
    <parent link="head_p_link"/>
    <child link="cam_link"/>
  </joint>
  <!-- camera link -->
  <link name="cam_link">
        </link>
  <!-- lidar joint -->
  <joint name="lidar_fixed" type="fixed">
    <origin rpy="0 0 0" xyz="0.0 0.045 0.10675"/>
    <parent link="head_p_link"/>
    <child link="lidar_link"/>
  </joint>
  <!-- lidar link -->
  <link name="lidar_link">
        </link>
  <!-- realsense joint -->
  <joint name="realsense_fixed" type="fixed">
    <!--<origin xyz="0.0749 0.02 0.0292" rpy="0 0 0"/>-->
    <origin rpy="0 0 0" xyz="0.0529 -0.009 0.0292"/>
    <parent link="head_p_link"/>
    <child link="realsense_link"/>
  </joint>
  <!-- realsense link -->
  <link name="realsense_link">
        </link>
  <!-- Gazebo Plugins -->
  <gazebo>
    <plugin filename="libgazebo_ros_control.so" name="gazebo_ros_control">
      <robotNamespace>/gogoro</robotNamespace>
    </plugin>
  </gazebo>
  <plugin filename="libgazebo_ros_joint_state_publisher.so" name="joint_state_publisher">
    <robotNamespace>gogoro</robotNamespace>
    <jointName>
            front_wheel_joint
        </jointName>
    <updateRate>100</updateRate>
    <alwaysOn>true</alwaysOn>
  </plugin>
  <!--
    <gazebo>
    <plugin name="ground_truth" filename="libgazebo_ros_p3d.so">
        <frameName>body</frameName>
        <bodyName>body</bodyName>
        <topicName>odom</topicName>
        <updateRate>100.0</updateRate>
    </plugin>
    </gazebo>
    -->
  <!-- Joints definitions -->
  <!-- Steering handle bar-->
  <joint name="steering_joint" type="revolute">
    <parent link="body"/>
    <child link="head"/>
    <origin rpy="0 -0.5235987755982988 0" xyz="471.816e-03 0 721.487e-03"/>
    <axis xyz="0 0 1"/>
    <limit effort="10000" lower="-0.5235987755982988" upper="0.5235987755982988" velocity="10000"/>
    <dynamics damping="0.0" friction="0.0"/>
  </joint>
  <!-- Fron wheel -->
  <joint name="front_wheel_joint" type="continuous">
    <parent link="head"/>
    <child link="front"/>
    <origin rpy="0 0.5235987755982988 0" xyz="-30e-03 0 -580.288e-03"/>
    <axis xyz="0 1 0"/>
    <limit velocity="1000" effort="10000000000"/>
  </joint>
  <!-- Rear wheel -->
  <joint name="rear_wheel_joint" type="continuous">
    <parent link="body"/>
    <child link="back"/>
    <origin rpy="0 0 0" xyz="-448.031e-03 0 201.999e-03"/>
    <axis xyz="0 1 0"/>
    <limit velocity="1000" effort="10000000000" /> 
  </joint>
  <!-- Transmissions-->
  <!--
  <transmission name="tran1">
    <type>transmission_interface/SimpleTransmission</type>
    <joint name="steering_joint">
      <hardwareInterface>hardware_interface/EffortJointInterface</hardwareInterface>
    </joint>
    <actuator name="motor1">
      <hardwareInterface>hardware_interface/EffortJointInterface</hardwareInterface>
      <mechanicalReduction>1</mechanicalReduction>
    </actuator>
  </transmission>
  <transmission name="tran2">
    <type>transmission_interface/SimpleTransmission</type>
    <joint name="rear_wheel_joint">
      <hardwareInterface>hardware_interface/VelocityJointInterface</hardwareInterface>
    </joint>
    <actuator name="motor2">
      <hardwareInterface>hardware_interface/VelocityJointInterface</hardwareInterface>
      <mechanicalReduction>1</mechanicalReduction>
    </actuator>
  </transmission>
  <transmission name="tran3">
    <type>transmission_interface/SimpleTransmission</type>
    <joint name="front_wheel_joint">
      <hardwareInterface>hardware_interface/VelocityJointInterface</hardwareInterface>
    </joint>
    <actuator name="motor3">
      <hardwareInterface>hardware_interface/VelocityJointInterface</hardwareInterface>
      <mechanicalReduction>1</mechanicalReduction>
    </actuator>
  </transmission>
-->
  <!-- Links definition-->
  <link name="body">
    <inertial>
      <origin rpy="0 0 0" xyz="-43.617e-03 0 486.763e-03"/>
      <mass value="79.2"/>
      <!-- 79.2 -->
      <inertia ixx="4.40515" ixy="0.117584" ixz="-1.66168" iyy="18.0137" iyz="0.098875" izz="14.8791"/>
      <inertia ixx="1" ixy="0" ixz="0" iyy="1" iyz="0" izz="1"/>
    </inertial>
        <collision>
            <origin xyz="0 0 0" rpy="0 0 0"/>
            <geometry>
                <mesh filename="package://gogoro_description/meshes/body.obj" scale="0.001 0.001 0.001"/>
            </geometry>
        </collision>
    <visual>
      <origin rpy="0 0 0" xyz="0 0 0"/>
      <geometry>
        <mesh filename="package://gogoro_description/meshes/body.obj" scale="0.001 0.001 0.001"/>
      </geometry>
      <material name="grey"/>
    </visual>
  </link>
  <!--2nd link-->
  <link name="head">
    <inertial>
      <origin rpy="0 0 0" xyz="0 0 0"/>
      <!-- <mass value="8.280e+00"/> -->
      <mass value="0.1"/>
      <!-- <inertia ixx="1.209e+01" ixy="0" ixz="5.265e+00" iyy="1.505e+01" iyz="0" izz="3.955e+01"/> -->
      <!-- <inertia ixx="1.209e-02" ixy="0" ixz="5.265e-03" iyy="1.505e-02" iyz="0" izz="3.955e-02"/> -->
      <inertia ixx="1" ixy="0" ixz="0" iyy="1" iyz="0" izz="1"/>
    </inertial>
    <collision>
      <origin rpy="0 0.5235987755982988 0" xyz="-769.287e-03 0 -388.918e-03"/>
      <geometry>
        <mesh filename="package://gogoro_description/meshes/head_bar.obj" scale="0.001 0.001 0.001"/>
      </geometry>
    </collision>
    <visual>
      <origin rpy="0 0.5235987755982988 0" xyz="-769.287e-03 0 -388.918e-03"/>
      <geometry>
        <mesh filename="package://gogoro_description/meshes/head_bar.obj" scale="0.001 0.001 0.001"/>
      </geometry>
      <material name="grey"/>
    </visual>
  </link>
  <link name="front">
    <inertial>
      <origin rpy="0 0 0" xyz="0 0 0"/>
      <!-- <mass value="2.753e+00"/> -->
      <mass value="0.1"/>
      <!-- <inertia ixx="0.8712e-03" ixy="0" ixz="0" iyy="7.728e-03" iyz="0" izz=".8712e-03"/> -->
      <inertia ixx="1" ixy="0" ixz="0" iyy="1" iyz="0" izz="1"/>
    </inertial>
    <collision name="collision_front">
      <origin rpy="0 0 0" xyz="-731.969e-03 0 -201.999e-03"/>
      <geometry>
        <mesh filename="package://gogoro_description/meshes/front_wheel.obj" scale="0.001 0.001 0.001"/>
        <!-- <sphere radius="1.0"/> -->
      </geometry>
    </collision>
    <visual>
      <origin rpy="0 0 0" xyz="-731.969e-03 0 -201.999e-03"/>
      <geometry>
        <mesh filename="package://gogoro_description/meshes/front_wheel.obj" scale="0.001 0.001 0.001"/>
      </geometry>
    </visual>
  </link>
  <!--4th link-->
  <link name="back">
    <inertial>
      <origin rpy="0 0 0" xyz="0 0 0"/>
      <!-- <mass value="2.753e+00"/> -->
      <mass value="0.1"/>
      <!-- <inertia ixx=".8712e-03" ixy="0" ixz="0" iyy="7.728e-03" iyz="0" izz=".8712e-03"/> -->
      <inertia ixx="1" ixy="0" ixz="0" iyy="1" iyz="0" izz="1"/>
    </inertial>
    <collision name="collision_back">
      <origin rpy="0 0 0" xyz="-731.969e-03 0 -201.999e-03"/>
      <geometry>
        <mesh filename="package://gogoro_description/meshes/front_wheel.obj" scale="0.001 0.001 0.001"/>
        <!-- <sphere radius="1.0"/> -->
      </geometry>
    </collision>
    <visual name="back_visual">
      <origin rpy="0 0 0" xyz="-731.969e-03 0 -201.999e-03"/>
      <geometry>
        <mesh filename="package://gogoro_description/meshes/front_wheel.obj" scale="0.001 0.001 0.001"/>
      </geometry>
      <material name="grey"/>
    </visual>
  </link>
  <gazebo reference="back">
    <mu1>0.2</mu1>
    <mu2>0.2</mu2>
    <maxVel>100.0</maxVel>
    <material>Gazebo/Orange</material>
  </gazebo>
  <gazebo reference="front">
    <mu1>0.2</mu1>
    <mu2>0.2</mu2>
    <maxVel>100.0</maxVel>
    <material>Gazebo/Orange</material>
  </gazebo>
  <!-- Connect Thormang3 pelvis to Gogoro's body -->
  <joint name="thormang3_fixed_gogoro" type="fixed">
    <origin rpy="0 0 0" xyz="0 0 -.9"/>
    <parent link="pelvis_link"/>
    <child link="body"/>
  </joint>
</robot>

